Workbook

Sheet Readme
A1: Population and Components of Change, 1960 to Present
A2: Office of Financial Management, Forecasting and Research Division
A5: Notes:
A7: Natural change is the difference between the number of live births and the number of deaths.
A9: Residual net migration is calculated as population change minus the amount of natural increase.
A11: Births and deaths are estimated for the most recent years due to a lag in reporting. The historical series may be revised in cases where more accurate data becomes available.
A13: Migration trends may not be reliable for smaller counties or counties with characteristics that make them difficult to estimate accurately. Erratic gains and losses are often apparent. Using a three year rolling average might stabilize migration estimates for smaller counties and those showing erratic trends.
A15: Data sources: Office of Financial Management April 1 population estimates, U.S. Census Bureau decennial census counts, and vital statistics from the Washington State Department of Health.
A17: 1The 2021 estimates in this table were revised November 30, 2021 after the 2020 Census P.L. 94-171 became available. These 2021 estimates supersede the estimates OFM released on June 30, 2021.
A19: Intercensal population estimates were used for 2011-2019 starting on February 10, 2022 after they became available.
A21: Last modified: 6/29/2026

Sheet Population
A1: Population and Components of Change, Total Population, 1960 to Present
A2: Office of Financial Management, Forecasting and Research Division
A4: County | B4: Jurisdiction | C4: Census Count of Total Population 1960 | D4: Estimate of Total Population 1961 | E4: Estimate of Total Population 1962 | F4: Estimate of Total Population 1963 | G4: Estimate of Total Population 1964 | H4: Estimate of Total Population 1965 | I4: Estimate of Total Population 1966 | J4: Estimate of Total Population 1967 | K4: Estimate of Total Population 1968 | L4: Estimate of Total Population 1969 | M4: Census Count of Total Population 1970 | N4: Estimate of Total Population 1971 | O4: Estimate of Total Population 1972 | P4: Estimate of Total Population 1973 | Q4: Estimate of Total Population 1974 | R4: Estimate of Total Population 1975 | S4: Estimate of Total Population 1976 | T4: Estimate of Total Population 1977 | U4: Estimate of Total Population 1978 | V4: Estimate of Total Population 1979 | W4: Census Count of Total Population 1980 | X4: Intercensal Estimate of Total Population 1981 | Y4: Intercensal Estimate of Total Population 1982 | Z4: Intercensal Estimate of Total Population 1983 | AA4: Intercensal Estimate of Total Population 1984 | AB4: Intercensal Estimate of Total Population 1985 | AC4: Intercensal Estimate of Total Population 1986 | AD4: Intercensal Estimate of Total Population 1987 | AE4: Intercensal Estimate of Total Population 1988 | AF4: Intercensal Estimate of Total Population 1989 | AG4: Census Count of Total Population 1990 | AH4: Intercensal Estimate of Total Population 1991 | AI4: Intercensal Estimate of Total Population 1992 | AJ4: Intercensal Estimate of Total Population 1993 | AK4: Intercensal Estimate of Total Population 1994 | AL4: Intercensal Estimate of Total Population 1995 | AM4: Intercensal Estimate of Total Population 1996 | AN4: Intercensal Estimate of Total Population 1997 | AO4: Intercensal Estimate of Total Population 1998 | AP4: Intercensal Estimate of Total Population 1999 | AQ4: Census Count of Total Population 2000 | AR4: Intercensal Estimate of Total Population 2001 | AS4: Intercensal Estimate of Total Population 2002 | AT4: Intercensal Estimate of Total Population 2003 | AU4: Intercensal Estimate of Total Population 2004 | AV4: Intercensal Estimate of Total Population 2005 | AW4: Intercensal Estimate of Total Population 2006 | AX4: Intercensal Estimate of Total Population 2007 | AY4: Intercensal Estimate of Total Population 2008 | AZ4: Intercensal Estimate of Total Population 2009 | BA4: Census Count of Total Population 2010 | BB4: Intercensal Estimate of Total Population 2011 | BC4: Intercensal Estimate of Total Population 2012 | BD4: Intercensal Estimate of Total Population 2013 | BE4: Intercensal Estimate of Total Population 2014 | BF4: Intercensal Estimate of Total Population 2015 | BG4: Intercensal Estimate of Total Population 2016 | BH4: Intercensal Estimate of Total Population 2017 | BI4: Intercensal Estimate of Total Population 2018 | BJ4: Intercensal Estimate of Total Population 2019 | BK4: Census Count of Total Population 2020 | BL4: Postcensal Estimate of Total Population 2021¹ | BM4: Postcensal Estimate of Total Population 2022 | BN4: Postcensal Estimate of Total Population 2023 | BO4: Postcensal Estimate of Total Population 2024 | BP4: Postcensal Estimate of Total Population 2025 | BQ4: Postcensal Estimate of Total Population 2026
A5: Adams | B5: Adams County | C5: 9929 | D5: 10100 | E5: 10300 | F5: 10100 | G5: 10200 | H5: 10400 | I5: 10600 | J5: 11000 | K5: 11000 | L5: 11400 | M5: 12014 | N5: 12200 | O5: 12600 | P5: 12700 | Q5: 12700 | R5: 13100 | S5: 13709 | T5: 13900 | U5: 14000 | V5: 13800 | W5: 13267 | X5: 13323 | Y5: 13407 | Z5: 13378 | AA5: 13389 | AB5: 13418 | AC5: 13430 | AD5: 13468 | AE5: 13503 | AF5: 13570 | AG5: 13603 | AH5: 13823 | AI5: 14063 | AJ5: 14335 | AK5: 14679 | AL5: 15030 | AM5: 15323 | AN5: 15698 | AO5: 15879 | AP5: 16151 | AQ5: 16428 | AR5: 16699 | AS5: 16911 | AT5: 17081 | AU5: 17489 | AV5: 17643 | AW5: 17690 | AX5: 17959 | AY5: 18214 | AZ5: 18421 | BA5: 18728 | BB5: 18849 | BC5: 19013 | BD5: 19172 | BE5: 19309 | BF5: 19451 | BG5: 19643 | BH5: 20068 | BI5: 20200 | BJ5: 20335 | BK5: 20613 | BL5: 20900 | BM5: 21100 | BN5: 21200 | BO5: 21475 | BP5: 21550 | BQ5: 22000
A6: Asotin | B6: Asotin County | C6: 12909 | D6: 12700 | E6: 13000 | F6: 13100 | G6: 12900 | H6: 12900 | I6: 13100 | J6: 13600 | K6: 13600 | L6: 13500 | M6: 13799 | N6: 14000 | O6: 14500 | P6: 14500 | Q6: 14700 | R6: 14800 | S6: 14900 | T6: 15500 | U6: 16000 | V6: 16400 | W6: 16823 | X6: 16804 | Y6: 16908 | Z6: 16839 | AA6: 17014 | AB6: 17154 | AC6: 17030 | AD6: 17096 | AE6: 17189 | AF6: 17326 | AG6: 17605 | AH6: 17677 | AI6: 17866 | AJ6: 18124 | AK6: 18666 | AL6: 18937 | AM6: 19622 | AN6: 19943 | AO6: 20202 | AP6: 20442 | AQ6: 20551 | AR6: 20650 | AS6: 20652 | AT6: 20709 | AU6: 20779 | AV6: 20939 | AW6: 21176 | AX6: 21413 | AY6: 21522 | AZ6: 21593 | BA6: 21623 | BB6: 21667 | BC6: 21680 | BD6: 21725 | BE6: 21790 | BF6: 21889 | BG6: 22003 | BH6: 22047 | BI6: 22112 | BJ6: 22182 | BK6: 22285 | BL6: 22500 | BM6: 22600 | BN6: 22650 | BO6: 22725 | BP6: 22750 | BQ6: 22950
A7: Benton | B7: Benton County | C7: 62070 | D7: 62300 | E7: 62800 | F7: 62400 | G7: 62300 | H7: 62500 | I7: 63100 | J7: 64300 | K7: 65200 | L7: 66000 | M7: 67540 | N7: 67500 | O7: 67700 | P7: 68200 | Q7: 70100 | R7: 74500 | S7: 80800 | T7: 86900 | U7: 94300 | V7: 102800 | W7: 109444 | X7: 110608 | Y7: 114265 | Z7: 113055 | AA7: 109932 | AB7: 108452 | AC7: 108841 | AD7: 109637 | AE7: 110408 | AF7: 111355 | AG7: 112560 | AH7: 114439 | AI7: 116503 | AJ7: 119374 | AK7: 123457 | AL7: 128359 | AM7: 132590 | AN7: 135620 | AO7: 137717 | AP7: 139498 | AQ7: 142475 | AR7: 145267 | AS7: 148290 | AT7: 151933 | AU7: 155874 | AV7: 159286 | AW7: 162255 | AX7: 165096 | AY7: 167598 | AZ7: 171402 | BA7: 175177 | BB7: 177675 | BC7: 180115 | BD7: 183504 | BE7: 186954 | BF7: 189520 | BG7: 191531 | BH7: 194724 | BI7: 198731 | BJ7: 202822 | BK7: 206873 | BL7: 209400 | BM7: 212300 | BN7: 215500 | BO7: 217850 | BP7: 219625 | BQ7: 223200
A8: Chelan | B8: Chelan County | C8: 40744 | D8: 40600 | E8: 40700 | F8: 40100 | G8: 40000 | H8: 39800 | I8: 39700 | J8: 40400 | K8: 40600 | L8: 40300 | M8: 41103 | N8: 41000 | O8: 38900 | P8: 39000 | Q8: 39700 | R8: 40200 | S8: 40700 | T8: 41400 | U8: 42600 | V8: 43800 | W8: 45061 | X8: 46050 | Y8: 45916 | Z8: 47454 | AA8: 48620 | AB8: 49250 | AC8: 49373 | AD8: 49514 | AE8: 50577 | AF8: 51073 | AG8: 52250 | AH8: 53436 | AI8: 54965 | AJ8: 56423 | AK8: 58319 | AL8: 60079 | AM8: 61240 | AN8: 62895 | AO8: 64199 | AP8: 65575 | AQ8: 66616 | AR8: 66896 | AS8: 67400 | AT8: 67507 | AU8: 68013 | AV8: 68963 | AW8: 69895 | AX8: 70773 | AY8: 71799 | AZ8: 72185 | BA8: 72453 | BB8: 72833 | BC8: 73166 | BD8: 73391 | BE8: 74405 | BF8: 74873 | BG8: 75500 | BH8: 76338 | BI8: 77465 | BJ8: 77944 | BK8: 79141 | BL8: 80000 | BM8: 80650 | BN8: 81500 | BO8: 82300 | BP8: 82900 | BQ8: 83525
A9: Clallam | B9: Clallam County | C9: 30022 | D9: 30400 | E9: 31000 | F9: 30900 | G9: 31300 | H9: 31900 | I9: 32500 | J9: 33600 | K9: 34300 | L9: 34600 | M9: 34770 | N9: 35700 | O9: 36300 | P9: 37700 | Q9: 39300 | R9: 41100 | S9: 43100 | T9: 44000 | U9: 46300 | V9: 49300 | W9: 51648 | X9: 51891 | Y9: 51485 | Z9: 52055 | AA9: 52547 | AB9: 52465 | AC9: 52837 | AD9: 52794 | AE9: 54396 | AF9: 55257 | AG9: 56204 | AH9: 57626 | AI9: 58275 | AJ9: 59155 | AK9: 59919 | AL9: 60548 | AM9: 61469 | AN9: 62037 | AO9: 62933 | AP9: 63425 | AQ9: 64179 | AR9: 64717 | AS9: 65398 | AT9: 65928 | AU9: 66725 | AV9: 67672 | AW9: 68948 | AX9: 69847 | AY9: 70629 | AZ9: 71027 | BA9: 71404 | BB9: 71810 | BC9: 72383 | BD9: 72771 | BE9: 73104 | BF9: 73482 | BG9: 74160 | BH9: 74873 | BI9: 75513 | BJ9: 76439 | BK9: 77155 | BL9: 77750 | BM9: 77625 | BN9: 78075 | BO9: 78550 | BP9: 78650 | BQ9: 79250
A10: Clark | B10: Clark County | C10: 93809 | D10: 96800 | E10: 99900 | F10: 102200 | G10: 105000 | H10: 108500 | I10: 111900 | J10: 117200 | K10: 122500 | L10: 129000 | M10: 128454 | N10: 133400 | O10: 141200 | P10: 145200 | Q10: 151600 | R10: 156800 | S10: 161000 | T10: 168400 | U10: 174500 | V10: 183500 | W10: 192227 | X10: 196475 | Y10: 199685 | Z10: 202165 | AA10: 203757 | AB10: 206744 | AC10: 210423 | AD10: 213961 | AE10: 219050 | AF10: 226188 | AG10: 238053 | AH10: 248417 | AI10: 255915 | AJ10: 264548 | AK10: 274423 | AL10: 286804 | AM10: 298364 | AN10: 310512 | AO10: 323892 | AP10: 334641 | AQ10: 345238 | AR10: 352715 | AS10: 364855 | AT10: 374091 | AU10: 385370 | AV10: 394600 | AW10: 404737 | AX10: 412692 | AY10: 419091 | AZ10: 423775 | BA10: 425363 | BB10: 428626 | BC10: 432320 | BD10: 437014 | BE10: 444450 | BF10: 452534 | BG10: 461869 | BH10: 472481 | BI10: 480952 | BJ10: 490693 | BK10: 503311 | BL10: 513100 | BM10: 520900 | BN10: 527400 | BO10: 536300 | BP10: 542400 | BQ10: 550000
A11: Columbia | B11: Columbia County | C11: 4569 | D11: 4600 | E11: 4400 | F11: 4500 | G11: 4500 | H11: 4300 | I11: 4400 | J11: 4500 | K11: 4700 | L11: 4500 | M11: 4439 | N11: 4400 | O11: 4400 | P11: 4300 | Q11: 4300 | R11: 4200 | S11: 4200 | T11: 4100 | U11: 4100 | V11: 4100 | W11: 4057 | X11: 4064 | Y11: 4060 | Z11: 4045 | AA11: 4045 | AB11: 4046 | AC11: 4044 | AD11: 4040 | AE11: 4045 | AF11: 4053 | AG11: 4024 | AH11: 4044 | AI11: 4041 | AJ11: 4047 | AK11: 4053 | AL11: 4051 | AM11: 4051 | AN11: 4056 | AO11: 4058 | AP11: 4062 | AQ11: 4064 | AR11: 4114 | AS11: 4115 | AT11: 4111 | AU11: 4122 | AV11: 4135 | AW11: 4128 | AX11: 4095 | AY11: 4099 | AZ11: 4097 | BA11: 4078 | BB11: 4069 | BC11: 4039 | BD11: 4037 | BE11: 4003 | BF11: 4007 | BG11: 3990 | BH11: 3979 | BI11: 3970 | BJ11: 3962 | BK11: 3952 | BL11: 3950 | BM11: 3950 | BN11: 3950 | BO11: 3975 | BP11: 3950 | BQ11: 3925
A12: Cowlitz | B12: Cowlitz County | C12: 57801 | D12: 58800 | E12: 59800 | F12: 60600 | G12: 61400 | H12: 62500 | I12: 63800 | J12: 65900 | K12: 68200 | L12: 69000 | M12: 68616 | N12: 69500 | O12: 69200 | P12: 69800 | Q12: 70900 | R12: 72100 | S12: 72400 | T12: 73700 | U12: 75700 | V12: 78000 | W12: 79548 | X12: 79609 | Y12: 78999 | Z12: 79334 | AA12: 79490 | AB12: 79259 | AC12: 78458 | AD12: 78930 | AE12: 79402 | AF12: 80867 | AG12: 82119 | AH12: 82862 | AI12: 83802 | AJ12: 84813 | AK12: 85921 | AL12: 87232 | AM12: 88531 | AN12: 89568 | AO12: 90600 | AP12: 91744 | AQ12: 92948 | AR12: 94081 | AS12: 94854 | AT12: 95849 | AU12: 96593 | AV12: 97673 | AW12: 99095 | AX12: 100377 | AY12: 101542 | AZ12: 102175 | BA12: 102410 | BB12: 102730 | BC12: 103097 | BD12: 103470 | BE12: 104043 | BF12: 104702 | BG12: 105419 | BH12: 106469 | BI12: 107782 | BJ12: 109315 | BK12: 110730 | BL12: 111500 | BM12: 112350 | BN12: 113000 | BO12: 113900 | BP12: 114500 | BQ12: 114900
A13: Douglas | B13: Douglas County | C13: 14890 | D13: 15100 | E13: 15000 | F13: 15200 | G13: 15300 | H13: 15300 | I13: 15600 | J13: 16100 | K13: 16600 | L13: 16600 | M13: 16787 | N13: 17600 | O13: 17600 | P13: 17400 | Q13: 17800 | R13: 18300 | S13: 19400 | T13: 20200 | U13: 21200 | V13: 21600 | W13: 22144 | X13: 22469 | Y13: 22477 | Z13: 22620 | AA13: 22794 | AB13: 23206 | AC13: 23585 | AD13: 23695 | AE13: 24429 | AF13: 25060 | AG13: 26205 | AH13: 27648 | AI13: 27423 | AJ13: 28143 | AK13: 28692 | AL13: 29312 | AM13: 29967 | AN13: 30548 | AO13: 31427 | AP13: 32035 | AQ13: 32603 | AR13: 32817 | AS13: 32871 | AT13: 33545 | AU13: 33944 | AV13: 34466 | AW13: 35505 | AX13: 36340 | AY13: 37238 | AZ13: 38036 | BA13: 38431 | BB13: 38676 | BC13: 38968 | BD13: 39269 | BE13: 39557 | BF13: 40008 | BG13: 40533 | BH13: 41042 | BI13: 41570 | BJ13: 42151 | BK13: 42938 | BL13: 43550 | BM13: 44000 | BN13: 44500 | BO13: 45150 | BP13: 45450 | BQ13: 45850
A14: Ferry | B14: Ferry County | C14: 3889 | D14: 4100 | E14: 3800 | F14: 3900 | G14: 3900 | H14: 3800 | I14: 3800 | J14: 3900 | K14: 3800 | L14: 3600 | M14: 3655 | N14: 3700 | O14: 4000 | P14: 4100 | Q14: 4400 | R14: 4600 | S14: 4800 | T14: 5147 | U14: 5300 | V14: 5700 | W14: 5811 | X14: 5930 | Y14: 6015 | Z14: 6054 | AA14: 6036 | AB14: 6016 | AC14: 6034 | AD14: 5871 | AE14: 6069 | AF14: 6150 | AG14: 6295 | AH14: 6366 | AI14: 6465 | AJ14: 6561 | AK14: 6648 | AL14: 6812 | AM14: 6950 | AN14: 7058 | AO14: 7135 | AP14: 7184 | AQ14: 7260 | AR14: 7340 | AS14: 7378 | AT14: 7397 | AU14: 7367 | AV14: 7405 | AW14: 7462 | AX14: 7484 | AY14: 7529 | AZ14: 7563 | BA14: 7551 | BB14: 7514 | BC14: 7477 | BD14: 7449 | BE14: 7404 | BF14: 7354 | BG14: 7319 | BH14: 7283 | BI14: 7234 | BJ14: 7209 | BK14: 7178 | BL14: 7250 | BM14: 7300 | BN14: 7300 | BO14: 7350 | BP14: 7350 | BQ14: 7350
A15: Franklin | B15: Franklin County | C15: 23342 | D15: 23500 | E15: 23900 | F15: 23800 | G15: 24100 | H15: 24200 | I15: 24400 | J15: 25200 | K15: 25600 | L15: 26100 | M15: 25816 | N15: 26000 | O15: 26800 | P15: 27200 | Q15: 27400 | R15: 27100 | S15: 29300 | T15: 30300 | U15: 32300 | V15: 34000 | W15: 35025 | X15: 35742 | Y15: 36688 | Z15: 36757 | AA15: 36987 | AB15: 36584 | AC15: 36388 | AD15: 36659 | AE15: 36910 | AF15: 37221 | AG15: 37473 | AH15: 38522 | AI15: 39077 | AJ15: 40092 | AK15: 41280 | AL15: 42516 | AM15: 43694 | AN15: 45180 | AO15: 46465 | AP15: 47900 | AQ15: 49347 | AR15: 50473 | AS15: 52286 | AT15: 54907 | AU15: 58576 | AV15: 62572 | AW15: 66371 | AX15: 69582 | AY15: 72230 | AZ15: 75111 | BA15: 78163 | BB15: 80493 | BC15: 82484 | BD15: 84251 | BE15: 86544 | BF15: 87053 | BG15: 88515 | BH15: 90036 | BI15: 92626 | BJ15: 94734 | BK15: 96749 | BL15: 98350 | BM15: 99750 | BN15: 101100 | BO15: 102300 | BP15: 103250 | BQ15: 105900
A16: Garfield | B16: Garfield County | C16: 2976 | D16: 2900 | E16: 2900 | F16: 2700 | G16: 2700 | H16: 2800 | I16: 2800 | J16: 2900 | K16: 2900 | L16: 2800 | M16: 2911 | N16: 3100 | O16: 3200 | P16: 3000 | Q16: 2800 | R16: 2800 | S16: 2900 | T16: 2900 | U16: 2700 | V16: 2600 | W16: 2468 | X16: 2466 | Y16: 2437 | Z16: 2447 | AA16: 2441 | AB16: 2418 | AC16: 2396 | AD16: 2334 | AE16: 2326 | AF16: 2253 | AG16: 2248 | AH16: 2259 | AI16: 2272 | AJ16: 2268 | AK16: 2310 | AL16: 2322 | AM16: 2344 | AN16: 2354 | AO16: 2360 | AP16: 2372 | AQ16: 2397 | AR16: 2382 | AS16: 2365 | AT16: 2348 | AU16: 2325 | AV16: 2315 | AW16: 2306 | AX16: 2287 | AY16: 2278 | AZ16: 2272 | BA16: 2266 | BB16: 2266 | BC16: 2260 | BD16: 2260 | BE16: 2252 | BF16: 2280 | BG16: 2266 | BH16: 2263 | BI16: 2269 | BJ16: 2278 | BK16: 2286 | BL16: 2300 | BM16: 2300 | BN16: 2300 | BO16: 2325 | BP16: 2300 | BQ16: 2300
... A44: State | B44: State Total | C44: 2853214 | D44: 2897000 | E44: 2948000 | F44: 2972000 | G44: 3008000 | H44: 3065000 | I44: 3125000 | J44: 3229000 | K44: 3336000 | L44: 3397000 | M44: 3413250 | N44: 3436300 | O44: 3430300 | P44: 3444300 | Q44: 3508700 | R44: 3567890 | S44: 3634891 | T44: 3715375 | U44: 3836200 | V44: 3979200 | W44: 4132353 | X44: 4229281 | Y44: 4276549 | Z44: 4307248 | AA44: 4354070 | AB44: 4415785 | AC44: 4462211 | AD44: 4527101 | AE44: 4616886 | AF44: 4728076 | AG44: 4866663 | AH44: 5000353 | AI44: 5091138 | AJ44: 5188009 | AK44: 5291577 | AL44: 5396569 | AM44: 5483103 | AN44: 5579140 | AO44: 5685459 | AP44: 5792214 | AQ44: 5894143 | AR44: 5970452 | AS44: 6059698 | AT44: 6126917 | AU44: 6208532 | AV44: 6298797 | AW44: 6420219 | AX44: 6525121 | AY44: 6608234 | AZ44: 6672263 | BA44: 6724540 | BB44: 6777903 | BC44: 6831660 | BD44: 6906026 | BE44: 7005209 | BF44: 7106620 | BG44: 7237219 | BH44: 7344073 | BI44: 7463479 | BJ44: 7581818 | BK44: 7706310 | BL44: 7766975 | BM44: 7864400 | BN44: 7951150 | BO44: 8035700 | BP44: 8115100 | BQ44: 8176300

Sheet Annual Change
A1: Population and Components of Change, Annual Change in Total Population, 1960 to Present
A2: Office of Financial Management, Forecasting and Research Division
A4: County | B4: Jurisdiction | C4: Spacer | D4: Annual Change in Total Population 1960-1961 | E4: Annual Change in Total Population 1961-1962 | F4: Annual Change in Total Population 1962-1963 | G4: Annual Change in Total Population 1963-1964 | H4: Annual Change in Total Population 1964-1965 | I4: Annual Change in Total Population 1965-1966 | J4: Annual Change in Total Population 1966-1967 | K4: Annual Change in Total Population 1967-1968 | L4: Annual Change in Total Population 1968-1969 | M4: Annual Change in Total Population 1969-1970 | N4: Annual Change in Total Population 1970-1971 | O4: Annual Change in Total Population 1971-1972 | P4: Annual Change in Total Population 1972-1973 | Q4: Annual Change in Total Population 1973-1974 | R4: Annual Change in Total Population 1974-1975 | S4: Annual Change in Total Population 1975-1976 | T4: Annual Change in Total Population 1976-1977 | U4: Annual Change in Total Population 1977-1978 | V4: Annual Change in Total Population 1978-1979 | W4: Annual Change in Total Population 1979-1980 | X4: Annual Change in Total Population 1980-1981 | Y4: Annual Change in Total Population 1981-1982 | Z4: Annual Change in Total Population 1982-1983 | AA4: Annual Change in Total Population 1983-1984 | AB4: Annual Change in Total Population 1984-1985 | AC4: Annual Change in Total Population 1985-1986 | AD4: Annual Change in Total Population 1986-1987 | AE4: Annual Change in Total Population 1987-1988 | AF4: Annual Change in Total Population 1988-1989 | AG4: Annual Change in Total Population 1989-1990 | AH4: Annual Change in Total Population 1990-1991 | AI4: Annual Change in Total Population 1991-1992 | AJ4: Annual Change in Total Population 1992-1993 | AK4: Annual Change in Total Population 1993-1994 | AL4: Annual Change in Total Population 1994-1995 | AM4: Annual Change in Total Population 1995-1996 | AN4: Annual Change in Total Population 1996-1997 | AO4: Annual Change in Total Population 1997-1998 | AP4: Annual Change in Total Population 1998-1999 | AQ4: Annual Change in Total Population 1999-2000 | AR4: Annual Change in Total Population 2000-2001 | AS4: Annual Change in Total Population 2001-2002 | AT4: Annual Change in Total Population 2002-2003 | AU4: Annual Change in Total Population 2003-2004 | AV4: Annual Change in Total Population 2004-2005 | AW4: Annual Change in Total Population 2005-2006 | AX4: Annual Change in Total Population 2006-2007 | AY4: Annual Change in Total Population 2007-2008 | AZ4: Annual Change in Total Population 2008-2009 | BA4: Annual Change in Total Population 2009-2010 | BB4: Annual Change in Total Population 2010-2011 | BC4: Annual Change in Total Population 2011-2012 | BD4: Annual Change in Total Population 2012-2013 | BE4: Annual Change in Total Population 2013-2014 | BF4: Annual Change in Total Population 2014-2015 | BG4: Annual Change in Total Population 2015-2016 | BH4: Annual Change in Total Population 2016-2017 | BI4: Annual Change in Total Population 2017-2018 | BJ4: Annual Change in Total Population 2018-2019 | BK4: Annual Change in Total Population 2019-2020 | BL4: Annual Change in Total Population 2020-2021¹ | BM4: Annual Change in Total Population 2021-2022 | BN4: Annual Change in Total Population 2022-2023 | BO4: Annual Change in Total Population 2023-2024 | BP4: Annual Change in Total Population 2024-2025 | BQ4: Annual Change in Total Population 2025-2026
A5: Adams | B5: Adams County | C5: . | D5: 171 | E5: 200 | F5: -200 | G5: 100 | H5: 200 | I5: 200 | J5: 400 | K5: 0 | L5: 400 | M5: 614 | N5: 186 | O5: 400 | P5: 100 | Q5: 0 | R5: 400 | S5: 609 | T5: 191 | U5: 100 | V5: -200 | W5: -533 | X5: 56 | Y5: 84 | Z5: -29 | AA5: 11 | AB5: 29 | AC5: 12 | AD5: 38 | AE5: 35 | AF5: 67 | AG5: 33 | AH5: 220 | AI5: 240 | AJ5: 272 | AK5: 344 | AL5: 351 | AM5: 293 | AN5: 375 | AO5: 181 | AP5: 272 | AQ5: 277 | AR5: 271 | AS5: 212 | AT5: 170 | AU5: 408 | AV5: 154 | AW5: 47 | AX5: 269 | AY5: 255 | AZ5: 207 | BA5: 307 | BB5: 121 | BC5: 164 | BD5: 159 | BE5: 137 | BF5: 142 | BG5: 192 | BH5: 425 | BI5: 132 | BJ5: 135 | BK5: 278 | BL5: 287 | BM5: 200 | BN5: 100 | BO5: 275 | BP5: 75 | BQ5: =Population!BQ5-Population!BP5 -> 450
A6: Asotin | B6: Asotin County | C6: . | D6: -209 | E6: 300 | F6: 100 | G6: -200 | H6: 0 | I6: 200 | J6: 500 | K6: 0 | L6: -100 | M6: 299 | N6: 201 | O6: 500 | P6: 0 | Q6: 200 | R6: 100 | S6: 100 | T6: 600 | U6: 500 | V6: 400 | W6: 423 | X6: -19 | Y6: 104 | Z6: -69 | AA6: 175 | AB6: 140 | AC6: -124 | AD6: 66 | AE6: 93 | AF6: 137 | AG6: 279 | AH6: 72 | AI6: 189 | AJ6: 258 | AK6: 542 | AL6: 271 | AM6: 685 | AN6: 321 | AO6: 259 | AP6: 240 | AQ6: 109 | AR6: 99 | AS6: 2 | AT6: 57 | AU6: 70 | AV6: 160 | AW6: 237 | AX6: 237 | AY6: 109 | AZ6: 71 | BA6: 30 | BB6: 44 | BC6: 13 | BD6: 45 | BE6: 65 | BF6: 99 | BG6: 114 | BH6: 44 | BI6: 65 | BJ6: 70 | BK6: 103 | BL6: 215 | BM6: 100 | BN6: 50 | BO6: 75 | BP6: 25 | BQ6: =Population!BQ6-Population!BP6 -> 200
A7: Benton | B7: Benton County | C7: . | D7: 230 | E7: 500 | F7: -400 | G7: -100 | H7: 200 | I7: 600 | J7: 1200 | K7: 900 | L7: 800 | M7: 1540 | N7: -40 | O7: 200 | P7: 500 | Q7: 1900 | R7: 4400 | S7: 6300 | T7: 6100 | U7: 7400 | V7: 8500 | W7: 6644 | X7: 1164 | Y7: 3657 | Z7: -1210 | AA7: -3123 | AB7: -1480 | AC7: 389 | AD7: 796 | AE7: 771 | AF7: 947 | AG7: 1205 | AH7: 1879 | AI7: 2064 | AJ7: 2871 | AK7: 4083 | AL7: 4902 | AM7: 4231 | AN7: 3030 | AO7: 2097 | AP7: 1781 | AQ7: 2977 | AR7: 2792 | AS7: 3023 | AT7: 3643 | AU7: 3941 | AV7: 3412 | AW7: 2969 | AX7: 2841 | AY7: 2502 | AZ7: 3804 | BA7: 3775 | BB7: 2498 | BC7: 2440 | BD7: 3389 | BE7: 3450 | BF7: 2566 | BG7: 2011 | BH7: 3193 | BI7: 4007 | BJ7: 4091 | BK7: 4051 | BL7: 2527 | BM7: 2900 | BN7: 3200 | BO7: 2350 | BP7: 1775 | BQ7: =Population!BQ7-Population!BP7 -> 3575
A8: Chelan | B8: Chelan County | C8: . | D8: -144 | E8: 100 | F8: -600 | G8: -100 | H8: -200 | I8: -100 | J8: 700 | K8: 200 | L8: -300 | M8: 803 | N8: -103 | O8: -2100 | P8: 100 | Q8: 700 | R8: 500 | S8: 500 | T8: 700 | U8: 1200 | V8: 1200 | W8: 1261 | X8: 989 | Y8: -134 | Z8: 1538 | AA8: 1166 | AB8: 630 | AC8: 123 | AD8: 141 | AE8: 1063 | AF8: 496 | AG8: 1177 | AH8: 1186 | AI8: 1529 | AJ8: 1458 | AK8: 1896 | AL8: 1760 | AM8: 1161 | AN8: 1655 | AO8: 1304 | AP8: 1376 | AQ8: 1041 | AR8: 280 | AS8: 504 | AT8: 107 | AU8: 506 | AV8: 950 | AW8: 932 | AX8: 878 | AY8: 1026 | AZ8: 386 | BA8: 268 | BB8: 380 | BC8: 333 | BD8: 225 | BE8: 1014 | BF8: 468 | BG8: 627 | BH8: 838 | BI8: 1127 | BJ8: 479 | BK8: 1197 | BL8: 859 | BM8: 650 | BN8: 850 | BO8: 800 | BP8: 600 | BQ8: =Population!BQ8-Population!BP8 -> 625
A9: Clallam | B9: Clallam County | C9: . | D9: 378 | E9: 600 | F9: -100 | G9: 400 | H9: 600 | I9: 600 | J9: 1100 | K9: 700 | L9: 300 | M9: 170 | N9: 930 | O9: 600 | P9: 1400 | Q9: 1600 | R9: 1800 | S9: 2000 | T9: 900 | U9: 2300 | V9: 3000 | W9: 2348 | X9: 243 | Y9: -406 | Z9: 570 | AA9: 492 | AB9: -82 | AC9: 372 | AD9: -43 | AE9: 1602 | AF9: 861 | AG9: 947 | AH9: 1422 | AI9: 649 | AJ9: 880 | AK9: 764 | AL9: 629 | AM9: 921 | AN9: 568 | AO9: 896 | AP9: 492 | AQ9: 754 | AR9: 538 | AS9: 681 | AT9: 530 | AU9: 797 | AV9: 947 | AW9: 1276 | AX9: 899 | AY9: 782 | AZ9: 398 | BA9: 377 | BB9: 406 | BC9: 573 | BD9: 388 | BE9: 333 | BF9: 378 | BG9: 678 | BH9: 713 | BI9: 640 | BJ9: 926 | BK9: 716 | BL9: 595 | BM9: -125 | BN9: 450 | BO9: 475 | BP9: 100 | BQ9: =Population!BQ9-Population!BP9 -> 600
A10: Clark | B10: Clark County | C10: . | D10: 2991 | E10: 3100 | F10: 2300 | G10: 2800 | H10: 3500 | I10: 3400 | J10: 5300 | K10: 5300 | L10: 6500 | M10: -546 | N10: 4946 | O10: 7800 | P10: 4000 | Q10: 6400 | R10: 5200 | S10: 4200 | T10: 7400 | U10: 6100 | V10: 9000 | W10: 8727 | X10: 4248 | Y10: 3210 | Z10: 2480 | AA10: 1592 | AB10: 2987 | AC10: 3679 | AD10: 3538 | AE10: 5089 | AF10: 7138 | AG10: 11865 | AH10: 10364 | AI10: 7498 | AJ10: 8633 | AK10: 9875 | AL10: 12381 | AM10: 11560 | AN10: 12148 | AO10: 13380 | AP10: 10749 | AQ10: 10597 | AR10: 7477 | AS10: 12140 | AT10: 9236 | AU10: 11279 | AV10: 9230 | AW10: 10137 | AX10: 7955 | AY10: 6399 | AZ10: 4684 | BA10: 1588 | BB10: 3263 | BC10: 3694 | BD10: 4694 | BE10: 7436 | BF10: 8084 | BG10: 9335 | BH10: 10612 | BI10: 8471 | BJ10: 9741 | BK10: 12618 | BL10: 9789 | BM10: 7800 | BN10: 6500 | BO10: 8900 | BP10: 6100 | BQ10: =Population!BQ10-Population!BP10 -> 7600
A11: Columbia | B11: Columbia County | C11: . | D11: 31 | E11: -200 | F11: 100 | G11: 0 | H11: -200 | I11: 100 | J11: 100 | K11: 200 | L11: -200 | M11: -61 | N11: -39 | O11: 0 | P11: -100 | Q11: 0 | R11: -100 | S11: 0 | T11: -100 | U11: 0 | V11: 0 | W11: -43 | X11: 7 | Y11: -4 | Z11: -15 | AA11: 0 | AB11: 1 | AC11: -2 | AD11: -4 | AE11: 5 | AF11: 8 | AG11: -29 | AH11: 20 | AI11: -3 | AJ11: 6 | AK11: 6 | AL11: -2 | AM11: 0 | AN11: 5 | AO11: 2 | AP11: 4 | AQ11: 2 | AR11: 50 | AS11: 1 | AT11: -4 | AU11: 11 | AV11: 13 | AW11: -7 | AX11: -33 | AY11: 4 | AZ11: -2 | BA11: -19 | BB11: -9 | BC11: -30 | BD11: -2 | BE11: -34 | BF11: 4 | BG11: -17 | BH11: -11 | BI11: -9 | BJ11: -8 | BK11: -10 | BL11: -2 | BM11: 0 | BN11: 0 | BO11: 25 | BP11: -25 | BQ11: =Population!BQ11-Population!BP11 -> -25
A12: Cowlitz | B12: Cowlitz County | C12: . | D12: 999 | E12: 1000 | F12: 800 | G12: 800 | H12: 1100 | I12: 1300 | J12: 2100 | K12: 2300 | L12: 800 | M12: -384 | N12: 884 | O12: -300 | P12: 600 | Q12: 1100 | R12: 1200 | S12: 300 | T12: 1300 | U12: 2000 | V12: 2300 | W12: 1548 | X12: 61 | Y12: -610 | Z12: 335 | AA12: 156 | AB12: -231 | AC12: -801 | AD12: 472 | AE12: 472 | AF12: 1465 | AG12: 1252 | AH12: 743 | AI12: 940 | AJ12: 1011 | AK12: 1108 | AL12: 1311 | AM12: 1299 | AN12: 1037 | AO12: 1032 | AP12: 1144 | AQ12: 1204 | AR12: 1133 | AS12: 773 | AT12: 995 | AU12: 744 | AV12: 1080 | AW12: 1422 | AX12: 1282 | AY12: 1165 | AZ12: 633 | BA12: 235 | BB12: 320 | BC12: 367 | BD12: 373 | BE12: 573 | BF12: 659 | BG12: 717 | BH12: 1050 | BI12: 1313 | BJ12: 1533 | BK12: 1415 | BL12: 770 | BM12: 850 | BN12: 650 | BO12: 900 | BP12: 600 | BQ12: =Population!BQ12-Population!BP12 -> 400
A13: Douglas | B13: Douglas County | C13: . | D13: 210 | E13: -100 | F13: 200 | G13: 100 | H13: 0 | I13: 300 | J13: 500 | K13: 500 | L13: 0 | M13: 187 | N13: 813 | O13: 0 | P13: -200 | Q13: 400 | R13: 500 | S13: 1100 | T13: 800 | U13: 1000 | V13: 400 | W13: 544 | X13: 325 | Y13: 8 | Z13: 143 | AA13: 174 | AB13: 412 | AC13: 379 | AD13: 110 | AE13: 734 | AF13: 631 | AG13: 1145 | AH13: 1443 | AI13: -225 | AJ13: 720 | AK13: 549 | AL13: 620 | AM13: 655 | AN13: 581 | AO13: 879 | AP13: 608 | AQ13: 568 | AR13: 214 | AS13: 54 | AT13: 674 | AU13: 399 | AV13: 522 | AW13: 1039 | AX13: 835 | AY13: 898 | AZ13: 798 | BA13: 395 | BB13: 245 | BC13: 292 | BD13: 301 | BE13: 288 | BF13: 451 | BG13: 525 | BH13: 509 | BI13: 528 | BJ13: 581 | BK13: 787 | BL13: 612 | BM13: 450 | BN13: 500 | BO13: 650 | BP13: 300 | BQ13: =Population!BQ13-Population!BP13 -> 400
A14: Ferry | B14: Ferry County | C14: . | D14: 211 | E14: -300 | F14: 100 | G14: 0 | H14: -100 | I14: 0 | J14: 100 | K14: -100 | L14: -200 | M14: 55 | N14: 45 | O14: 300 | P14: 100 | Q14: 300 | R14: 200 | S14: 200 | T14: 347 | U14: 153 | V14: 400 | W14: 111 | X14: 119 | Y14: 85 | Z14: 39 | AA14: -18 | AB14: -20 | AC14: 18 | AD14: -163 | AE14: 198 | AF14: 81 | AG14: 145 | AH14: 71 | AI14: 99 | AJ14: 96 | AK14: 87 | AL14: 164 | AM14: 138 | AN14: 108 | AO14: 77 | AP14: 49 | AQ14: 76 | AR14: 80 | AS14: 38 | AT14: 19 | AU14: -30 | AV14: 38 | AW14: 57 | AX14: 22 | AY14: 45 | AZ14: 34 | BA14: -12 | BB14: -37 | BC14: -37 | BD14: -28 | BE14: -45 | BF14: -50 | BG14: -35 | BH14: -36 | BI14: -49 | BJ14: -25 | BK14: -31 | BL14: 72 | BM14: 50 | BN14: 0 | BO14: 50 | BP14: 0 | BQ14: =Population!BQ14-Population!BP14 -> 0
A15: Franklin | B15: Franklin County | C15: . | D15: 158 | E15: 400 | F15: -100 | G15: 300 | H15: 100 | I15: 200 | J15: 800 | K15: 400 | L15: 500 | M15: -284 | N15: 184 | O15: 800 | P15: 400 | Q15: 200 | R15: -300 | S15: 2200 | T15: 1000 | U15: 2000 | V15: 1700 | W15: 1025 | X15: 717 | Y15: 946 | Z15: 69 | AA15: 230 | AB15: -403 | AC15: -196 | AD15: 271 | AE15: 251 | AF15: 311 | AG15: 252 | AH15: 1049 | AI15: 555 | AJ15: 1015 | AK15: 1188 | AL15: 1236 | AM15: 1178 | AN15: 1486 | AO15: 1285 | AP15: 1435 | AQ15: 1447 | AR15: 1126 | AS15: 1813 | AT15: 2621 | AU15: 3669 | AV15: 3996 | AW15: 3799 | AX15: 3211 | AY15: 2648 | AZ15: 2881 | BA15: 3052 | BB15: 2330 | BC15: 1991 | BD15: 1767 | BE15: 2293 | BF15: 509 | BG15: 1462 | BH15: 1521 | BI15: 2590 | BJ15: 2108 | BK15: 2015 | BL15: 1601 | BM15: 1400 | BN15: 1350 | BO15: 1200 | BP15: 950 | BQ15: =Population!BQ15-Population!BP15 -> 2650
A16: Garfield | B16: Garfield County | C16: . | D16: -76 | E16: 0 | F16: -200 | G16: 0 | H16: 100 | I16: 0 | J16: 100 | K16: 0 | L16: -100 | M16: 111 | N16: 189 | O16: 100 | P16: -200 | Q16: -200 | R16: 0 | S16: 100 | T16: 0 | U16: -200 | V16: -100 | W16: -132 | X16: -2 | Y16: -29 | Z16: 10 | AA16: -6 | AB16: -23 | AC16: -22 | AD16: -62 | AE16: -8 | AF16: -73 | AG16: -5 | AH16: 11 | AI16: 13 | AJ16: -4 | AK16: 42 | AL16: 12 | AM16: 22 | AN16: 10 | AO16: 6 | AP16: 12 | AQ16: 25 | AR16: -15 | AS16: -17 | AT16: -17 | AU16: -23 | AV16: -10 | AW16: -9 | AX16: -19 | AY16: -9 | AZ16: -6 | BA16: -6 | BB16: 0 | BC16: -6 | BD16: 0 | BE16: -8 | BF16: 28 | BG16: -14 | BH16: -3 | BI16: 6 | BJ16: 9 | BK16: 8 | BL16: 14 | BM16: 0 | BN16: 0 | BO16: 25 | BP16: -25 | BQ16: =Population!BQ16-Population!BP16 -> 0
... A44: State | B44: State Total | C44: . | D44: 43786 | E44: 51000 | F44: 24000 | G44: 36000 | H44: 57000 | I44: 60000 | J44: 104000 | K44: 107000 | L44: 61000 | M44: 16250 | N44: 23050 | O44: -6000 | P44: 14000 | Q44: 64400 | R44: 59190 | S44: 67001 | T44: 80484 | U44: 120825 | V44: 143000 | W44: 153153 | X44: 96928 | Y44: 47268 | Z44: 30699 | AA44: 46822 | AB44: 61715 | AC44: 46426 | AD44: 64890 | AE44: 89785 | AF44: 111190 | AG44: 138587 | AH44: 133690 | AI44: 90785 | AJ44: 96871 | AK44: 103568 | AL44: 104992 | AM44: 86534 | AN44: 96037 | AO44: 106319 | AP44: 106755 | AQ44: 101929 | AR44: 76309 | AS44: 89246 | AT44: 67219 | AU44: 81615 | AV44: 90265 | AW44: 121422 | AX44: 104902 | AY44: 83113 | AZ44: 64029 | BA44: 52277 | BB44: 53363 | BC44: 53757 | BD44: 74366 | BE44: 99183 | BF44: 101411 | BG44: 130599 | BH44: 106854 | BI44: 119406 | BJ44: 118339 | BK44: 124492 | BL44: 60665 | BM44: 97425 | BN44: 86750 | BO44: 84550 | BP44: 79400 | BQ44: =Population!BQ44-Population!BP44 -> 61200
BK47: .

Sheet Annual % Change
A1: Population and Components of Change, Annual Percent Change in Total Population, 1960 to Present
A2: Office of Financial Management, Forecasting and Research Division
A4: County | B4: Jurisdiction | C4: Spacer | D4: Annual % Change in Total Population 1960-1961 | E4: Annual % Change in Total Population 1961-1962 | F4: Annual % Change in Total Population 1962-1963 | G4: Annual % Change in Total Population 1963-1964 | H4: Annual % Change in Total Population 1964-1965 | I4: Annual % Change in Total Population 1965-1966 | J4: Annual % Change in Total Population 1966-1967 | K4: Annual % Change in Total Population 1967-1968 | L4: Annual % Change in Total Population 1968-1969 | M4: Annual % Change in Total Population 1969-1970 | N4: Annual % Change in Total Population 1970-1971 | O4: Annual % Change in Total Population 1971-1972 | P4: Annual % Change in Total Population 1972-1973 | Q4: Annual % Change in Total Population 1973-1974 | R4: Annual % Change in Total Population 1974-1975 | S4: Annual % Change in Total Population 1975-1976 | T4: Annual % Change in Total Population 1976-1977 | U4: Annual % Change in Total Population 1977-1978 | V4: Annual % Change in Total Population 1978-1979 | W4: Annual % Change in Total Population 1979-1980 | X4: Annual % Change in Total Population 1980-1981 | Y4: Annual % Change in Total Population 1981-1982 | Z4: Annual % Change in Total Population 1982-1983 | AA4: Annual % Change in Total Population 1983-1984 | AB4: Annual % Change in Total Population 1984-1985 | AC4: Annual % Change in Total Population 1985-1986 | AD4: Annual % Change in Total Population 1986-1987 | AE4: Annual % Change in Total Population 1987-1988 | AF4: Annual % Change in Total Population 1988-1989 | AG4: Annual % Change in Total Population 1989-1990 | AH4: Annual % Change in Total Population 1990-1991 | AI4: Annual % Change in Total Population 1991-1992 | AJ4: Annual % Change in Total Population 1992-1993 | AK4: Annual % Change in Total Population 1993-1994 | AL4: Annual % Change in Total Population 1994-1995 | AM4: Annual % Change in Total Population 1995-1996 | AN4: Annual % Change in Total Population 1996-1997 | AO4: Annual % Change in Total Population 1997-1998 | AP4: Annual % Change in Total Population 1998-1999 | AQ4: Annual % Change in Total Population 1999-2000 | AR4: Annual % Change in Total Population 2000-2001 | AS4: Annual % Change in Total Population 2001-2002 | AT4: Annual % Change in Total Population 2002-2003 | AU4: Annual % Change in Total Population 2003-2004 | AV4: Annual % Change in Total Population 2004-2005 | AW4: Annual % Change in Total Population 2005-2006 | AX4: Annual % Change in Total Population 2006-2007 | AY4: Annual % Change in Total Population 2007-2008 | AZ4: Annual % Change in Total Population 2008-2009 | BA4: Annual % Change in Total Population 2009-2010 | BB4: Annual % Change in Total Population 2010-2011 | BC4: Annual % Change in Total Population 2011-2012 | BD4: Annual % Change in Total Population 2012-2013 | BE4: Annual % Change in Total Population 2013-2014 | BF4: Annual % Change in Total Population 2014-2015 | BG4: Annual % Change in Total Population 2015-2016 | BH4: Annual % Change in Total Population 2016-2017 | BI4: Annual % Change in Total Population 2017-2018 | BJ4: Annual % Change in Total Population 2018-2019 | BK4: Annual % Change in Total Population 2019-2020 | BL4: Annual % Change in Total Population 2020-2021¹ | BM4: Annual % Change in Total Population 2021-2022 | BN4: Annual % Change in Total Population 2022-2023 | BO4: Annual % Change in Total Population 2023-2024 | BP4: Annual % Change in Total Population 2024-2025 | BQ4: Annual % Change in Total Population 2025-2026
A5: Adams | B5: Adams County | C5: . | D5: 1.72 | E5: 1.98 | F5: -1.94 | G5: 0.99 | H5: 1.96 | I5: 1.92 | J5: 3.77 | K5: 0 | L5: 3.64 | M5: 5.39 | N5: 1.55 | O5: 3.28 | P5: 0.79 | Q5: 0 | R5: 3.15 | S5: 4.65 | T5: 1.39 | U5: 0.72 | V5: -1.43 | W5: -3.86 | X5: 0.42 | Y5: 0.63 | Z5: -0.22 | AA5: 0.08 | AB5: 0.22 | AC5: 0.09 | AD5: 0.28 | AE5: 0.26 | AF5: 0.5 | AG5: 0.24 | AH5: 1.62 | AI5: 1.74 | AJ5: 1.93 | AK5: 2.4 | AL5: 2.39 | AM5: 1.95 | AN5: 2.45 | AO5: 1.15 | AP5: 1.71 | AQ5: 1.72 | AR5: 1.65 | AS5: 1.27 | AT5: 1.01 | AU5: 2.39 | AV5: 0.88 | AW5: 0.27 | AX5: 1.52 | AY5: 1.42 | AZ5: 1.14 | BA5: 1.67 | BB5: 0.65 | BC5: 0.87 | BD5: 0.84 | BE5: 0.71 | BF5: 0.74 | BG5: 0.99 | BH5: 2.16 | BI5: 0.66 | BJ5: 0.67 | BK5: 1.37 | BL5: 1.39 | BM5: 0.96 | BN5: 0.47 | BO5: 1.3 | BP5: 0.35 | BQ5: =ROUND(('Annual Change'!BQ5/Population!BP5)*100,2) -> 2.09
A6: Asotin | B6: Asotin County | C6: . | D6: -1.62 | E6: 2.36 | F6: 0.77 | G6: -1.53 | H6: 0 | I6: 1.55 | J6: 3.82 | K6: 0 | L6: -0.74 | M6: 2.21 | N6: 1.46 | O6: 3.57 | P6: 0 | Q6: 1.38 | R6: 0.68 | S6: 0.68 | T6: 4.03 | U6: 3.23 | V6: 2.5 | W6: 2.58 | X6: -0.11 | Y6: 0.62 | Z6: -0.41 | AA6: 1.04 | AB6: 0.82 | AC6: -0.72 | AD6: 0.39 | AE6: 0.54 | AF6: 0.8 | AG6: 1.61 | AH6: 0.41 | AI6: 1.07 | AJ6: 1.44 | AK6: 2.99 | AL6: 1.45 | AM6: 3.62 | AN6: 1.64 | AO6: 1.3 | AP6: 1.19 | AQ6: 0.53 | AR6: 0.48 | AS6: 0.01 | AT6: 0.28 | AU6: 0.34 | AV6: 0.77 | AW6: 1.13 | AX6: 1.12 | AY6: 0.51 | AZ6: 0.33 | BA6: 0.14 | BB6: 0.2 | BC6: 0.06 | BD6: 0.21 | BE6: 0.3 | BF6: 0.45 | BG6: 0.52 | BH6: 0.2 | BI6: 0.29 | BJ6: 0.32 | BK6: 0.46 | BL6: 0.96 | BM6: 0.44 | BN6: 0.22 | BO6: 0.33 | BP6: 0.11 | BQ6: =ROUND(('Annual Change'!BQ6/Population!BP6)*100,2) -> 0.88
A7: Benton | B7: Benton County | C7: . | D7: 0.37 | E7: 0.8 | F7: -0.64 | G7: -0.16 | H7: 0.32 | I7: 0.96 | J7: 1.9 | K7: 1.4 | L7: 1.23 | M7: 2.33 | N7: -0.06 | O7: 0.3 | P7: 0.74 | Q7: 2.79 | R7: 6.28 | S7: 8.46 | T7: 7.55 | U7: 8.52 | V7: 9.01 | W7: 6.46 | X7: 1.06 | Y7: 3.31 | Z7: -1.06 | AA7: -2.76 | AB7: -1.35 | AC7: 0.36 | AD7: 0.73 | AE7: 0.7 | AF7: 0.86 | AG7: 1.08 | AH7: 1.67 | AI7: 1.8 | AJ7: 2.46 | AK7: 3.42 | AL7: 3.97 | AM7: 3.3 | AN7: 2.29 | AO7: 1.55 | AP7: 1.29 | AQ7: 2.13 | AR7: 1.96 | AS7: 2.08 | AT7: 2.46 | AU7: 2.59 | AV7: 2.19 | AW7: 1.86 | AX7: 1.75 | AY7: 1.52 | AZ7: 2.27 | BA7: 2.2 | BB7: 1.43 | BC7: 1.37 | BD7: 1.88 | BE7: 1.88 | BF7: 1.37 | BG7: 1.06 | BH7: 1.67 | BI7: 2.06 | BJ7: 2.06 | BK7: 2 | BL7: 1.22 | BM7: 1.38 | BN7: 1.51 | BO7: 1.09 | BP7: 0.81 | BQ7: =ROUND(('Annual Change'!BQ7/Population!BP7)*100,2) -> 1.63
A8: Chelan | B8: Chelan County | C8: . | D8: -0.35 | E8: 0.25 | F8: -1.47 | G8: -0.25 | H8: -0.5 | I8: -0.25 | J8: 1.76 | K8: 0.5 | L8: -0.74 | M8: 1.99 | N8: -0.25 | O8: -5.12 | P8: 0.26 | Q8: 1.79 | R8: 1.26 | S8: 1.24 | T8: 1.72 | U8: 2.9 | V8: 2.82 | W8: 2.88 | X8: 2.19 | Y8: -0.29 | Z8: 3.35 | AA8: 2.46 | AB8: 1.3 | AC8: 0.25 | AD8: 0.29 | AE8: 2.15 | AF8: 0.98 | AG8: 2.3 | AH8: 2.27 | AI8: 2.86 | AJ8: 2.65 | AK8: 3.36 | AL8: 3.02 | AM8: 1.93 | AN8: 2.7 | AO8: 2.07 | AP8: 2.14 | AQ8: 1.59 | AR8: 0.42 | AS8: 0.75 | AT8: 0.16 | AU8: 0.75 | AV8: 1.4 | AW8: 1.35 | AX8: 1.26 | AY8: 1.45 | AZ8: 0.54 | BA8: 0.37 | BB8: 0.52 | BC8: 0.46 | BD8: 0.31 | BE8: 1.38 | BF8: 0.63 | BG8: 0.84 | BH8: 1.11 | BI8: 1.48 | BJ8: 0.62 | BK8: 1.54 | BL8: 1.09 | BM8: 0.81 | BN8: 1.05 | BO8: 0.98 | BP8: 0.73 | BQ8: =ROUND(('Annual Change'!BQ8/Population!BP8)*100,2) -> 0.75
A9: Clallam | B9: Clallam County | C9: . | D9: 1.26 | E9: 1.97 | F9: -0.32 | G9: 1.29 | H9: 1.92 | I9: 1.88 | J9: 3.38 | K9: 2.08 | L9: 0.87 | M9: 0.49 | N9: 2.67 | O9: 1.68 | P9: 3.86 | Q9: 4.24 | R9: 4.58 | S9: 4.87 | T9: 2.09 | U9: 5.23 | V9: 6.48 | W9: 4.76 | X9: 0.47 | Y9: -0.78 | Z9: 1.11 | AA9: 0.95 | AB9: -0.16 | AC9: 0.71 | AD9: -0.08 | AE9: 3.03 | AF9: 1.58 | AG9: 1.71 | AH9: 2.53 | AI9: 1.13 | AJ9: 1.51 | AK9: 1.29 | AL9: 1.05 | AM9: 1.52 | AN9: 0.92 | AO9: 1.44 | AP9: 0.78 | AQ9: 1.19 | AR9: 0.84 | AS9: 1.05 | AT9: 0.81 | AU9: 1.21 | AV9: 1.42 | AW9: 1.89 | AX9: 1.3 | AY9: 1.12 | AZ9: 0.56 | BA9: 0.53 | BB9: 0.57 | BC9: 0.8 | BD9: 0.54 | BE9: 0.46 | BF9: 0.52 | BG9: 0.92 | BH9: 0.96 | BI9: 0.85 | BJ9: 1.23 | BK9: 0.94 | BL9: 0.77 | BM9: -0.16 | BN9: 0.58 | BO9: 0.61 | BP9: 0.13 | BQ9: =ROUND(('Annual Change'!BQ9/Population!BP9)*100,2) -> 0.76
A10: Clark | B10: Clark County | C10: . | D10: 3.19 | E10: 3.2 | F10: 2.3 | G10: 2.74 | H10: 3.33 | I10: 3.13 | J10: 4.74 | K10: 4.52 | L10: 5.31 | M10: -0.42 | N10: 3.85 | O10: 5.85 | P10: 2.83 | Q10: 4.41 | R10: 3.43 | S10: 2.68 | T10: 4.6 | U10: 3.62 | V10: 5.16 | W10: 4.76 | X10: 2.21 | Y10: 1.63 | Z10: 1.24 | AA10: 0.79 | AB10: 1.47 | AC10: 1.78 | AD10: 1.68 | AE10: 2.38 | AF10: 3.26 | AG10: 5.25 | AH10: 4.35 | AI10: 3.02 | AJ10: 3.37 | AK10: 3.73 | AL10: 4.51 | AM10: 4.03 | AN10: 4.07 | AO10: 4.31 | AP10: 3.32 | AQ10: 3.17 | AR10: 2.17 | AS10: 3.44 | AT10: 2.53 | AU10: 3.02 | AV10: 2.4 | AW10: 2.57 | AX10: 1.97 | AY10: 1.55 | AZ10: 1.12 | BA10: 0.37 | BB10: 0.77 | BC10: 0.86 | BD10: 1.09 | BE10: 1.7 | BF10: 1.82 | BG10: 2.06 | BH10: 2.3 | BI10: 1.79 | BJ10: 2.03 | BK10: 2.57 | BL10: 1.94 | BM10: 1.52 | BN10: 1.25 | BO10: 1.69 | BP10: 1.14 | BQ10: =ROUND(('Annual Change'!BQ10/Population!BP10)*100,2) -> 1.4
A11: Columbia | B11: Columbia County | C11: . | D11: 0.68 | E11: -4.35 | F11: 2.27 | G11: 0 | H11: -4.44 | I11: 2.33 | J11: 2.27 | K11: 4.44 | L11: -4.26 | M11: -1.36 | N11: -0.88 | O11: 0 | P11: -2.27 | Q11: 0 | R11: -2.33 | S11: 0 | T11: -2.38 | U11: 0 | V11: 0 | W11: -1.05 | X11: 0.17 | Y11: -0.1 | Z11: -0.37 | AA11: 0 | AB11: 0.02 | AC11: -0.05 | AD11: -0.1 | AE11: 0.12 | AF11: 0.2 | AG11: -0.72 | AH11: 0.5 | AI11: -0.07 | AJ11: 0.15 | AK11: 0.15 | AL11: -0.05 | AM11: 0 | AN11: 0.12 | AO11: 0.05 | AP11: 0.1 | AQ11: 0.05 | AR11: 1.23 | AS11: 0.02 | AT11: -0.1 | AU11: 0.27 | AV11: 0.32 | AW11: -0.17 | AX11: -0.8 | AY11: 0.1 | AZ11: -0.05 | BA11: -0.46 | BB11: -0.22 | BC11: -0.74 | BD11: -0.05 | BE11: -0.84 | BF11: 0.1 | BG11: -0.42 | BH11: -0.28 | BI11: -0.23 | BJ11: -0.2 | BK11: -0.25 | BL11: -0.05 | BM11: 0 | BN11: 0 | BO11: 0.63 | BP11: -0.63 | BQ11: =ROUND(('Annual Change'!BQ11/Population!BP11)*100,2) -> -0.63
A12: Cowlitz | B12: Cowlitz County | C12: . | D12: 1.73 | E12: 1.7 | F12: 1.34 | G12: 1.32 | H12: 1.79 | I12: 2.08 | J12: 3.29 | K12: 3.49 | L12: 1.17 | M12: -0.56 | N12: 1.29 | O12: -0.43 | P12: 0.87 | Q12: 1.58 | R12: 1.69 | S12: 0.42 | T12: 1.8 | U12: 2.71 | V12: 3.04 | W12: 1.98 | X12: 0.08 | Y12: -0.77 | Z12: 0.42 | AA12: 0.2 | AB12: -0.29 | AC12: -1.01 | AD12: 0.6 | AE12: 0.6 | AF12: 1.85 | AG12: 1.55 | AH12: 0.9 | AI12: 1.13 | AJ12: 1.21 | AK12: 1.31 | AL12: 1.53 | AM12: 1.49 | AN12: 1.17 | AO12: 1.15 | AP12: 1.26 | AQ12: 1.31 | AR12: 1.22 | AS12: 0.82 | AT12: 1.05 | AU12: 0.78 | AV12: 1.12 | AW12: 1.46 | AX12: 1.29 | AY12: 1.16 | AZ12: 0.62 | BA12: 0.23 | BB12: 0.31 | BC12: 0.36 | BD12: 0.36 | BE12: 0.55 | BF12: 0.63 | BG12: 0.68 | BH12: 1 | BI12: 1.23 | BJ12: 1.42 | BK12: 1.29 | BL12: 0.7 | BM12: 0.76 | BN12: 0.58 | BO12: 0.8 | BP12: 0.53 | BQ12: =ROUND(('Annual Change'!BQ12/Population!BP12)*100,2) -> 0.35
A13: Douglas | B13: Douglas County | C13: . | D13: 1.41 | E13: -0.66 | F13: 1.33 | G13: 0.66 | H13: 0 | I13: 1.96 | J13: 3.21 | K13: 3.11 | L13: 0 | M13: 1.13 | N13: 4.84 | O13: 0 | P13: -1.14 | Q13: 2.3 | R13: 2.81 | S13: 6.01 | T13: 4.12 | U13: 4.95 | V13: 1.89 | W13: 2.52 | X13: 1.47 | Y13: 0.04 | Z13: 0.64 | AA13: 0.77 | AB13: 1.81 | AC13: 1.63 | AD13: 0.47 | AE13: 3.1 | AF13: 2.58 | AG13: 4.57 | AH13: 5.51 | AI13: -0.81 | AJ13: 2.63 | AK13: 1.95 | AL13: 2.16 | AM13: 2.23 | AN13: 1.94 | AO13: 2.88 | AP13: 1.93 | AQ13: 1.77 | AR13: 0.66 | AS13: 0.16 | AT13: 2.05 | AU13: 1.19 | AV13: 1.54 | AW13: 3.01 | AX13: 2.35 | AY13: 2.47 | AZ13: 2.14 | BA13: 1.04 | BB13: 0.64 | BC13: 0.75 | BD13: 0.77 | BE13: 0.73 | BF13: 1.14 | BG13: 1.31 | BH13: 1.26 | BI13: 1.29 | BJ13: 1.4 | BK13: 1.87 | BL13: 1.43 | BM13: 1.03 | BN13: 1.14 | BO13: 1.46 | BP13: 0.66 | BQ13: =ROUND(('Annual Change'!BQ13/Population!BP13)*100,2) -> 0.88
A14: Ferry | B14: Ferry County | C14: . | D14: 5.43 | E14: -7.32 | F14: 2.63 | G14: 0 | H14: -2.56 | I14: 0 | J14: 2.63 | K14: -2.56 | L14: -5.26 | M14: 1.53 | N14: 1.23 | O14: 8.11 | P14: 2.5 | Q14: 7.32 | R14: 4.55 | S14: 4.35 | T14: 7.23 | U14: 2.97 | V14: 7.55 | W14: 1.95 | X14: 2.05 | Y14: 1.43 | Z14: 0.65 | AA14: -0.3 | AB14: -0.33 | AC14: 0.3 | AD14: -2.7 | AE14: 3.37 | AF14: 1.33 | AG14: 2.36 | AH14: 1.13 | AI14: 1.56 | AJ14: 1.48 | AK14: 1.33 | AL14: 2.47 | AM14: 2.03 | AN14: 1.55 | AO14: 1.09 | AP14: 0.69 | AQ14: 1.06 | AR14: 1.1 | AS14: 0.52 | AT14: 0.26 | AU14: -0.41 | AV14: 0.52 | AW14: 0.77 | AX14: 0.29 | AY14: 0.6 | AZ14: 0.45 | BA14: -0.16 | BB14: -0.49 | BC14: -0.49 | BD14: -0.37 | BE14: -0.6 | BF14: -0.68 | BG14: -0.48 | BH14: -0.49 | BI14: -0.67 | BJ14: -0.35 | BK14: -0.43 | BL14: 1 | BM14: 0.69 | BN14: 0 | BO14: 0.68 | BP14: 0 | BQ14: =ROUND(('Annual Change'!BQ14/Population!BP14)*100,2) -> 0
A15: Franklin | B15: Franklin County | C15: . | D15: 0.68 | E15: 1.7 | F15: -0.42 | G15: 1.26 | H15: 0.41 | I15: 0.83 | J15: 3.28 | K15: 1.59 | L15: 1.95 | M15: -1.09 | N15: 0.71 | O15: 3.08 | P15: 1.49 | Q15: 0.74 | R15: -1.09 | S15: 8.12 | T15: 3.41 | U15: 6.6 | V15: 5.26 | W15: 3.01 | X15: 2.05 | Y15: 2.65 | Z15: 0.19 | AA15: 0.63 | AB15: -1.09 | AC15: -0.54 | AD15: 0.74 | AE15: 0.68 | AF15: 0.84 | AG15: 0.68 | AH15: 2.8 | AI15: 1.44 | AJ15: 2.6 | AK15: 2.96 | AL15: 2.99 | AM15: 2.77 | AN15: 3.4 | AO15: 2.84 | AP15: 3.09 | AQ15: 3.02 | AR15: 2.28 | AS15: 3.59 | AT15: 5.01 | AU15: 6.68 | AV15: 6.82 | AW15: 6.07 | AX15: 4.84 | AY15: 3.81 | AZ15: 3.99 | BA15: 4.06 | BB15: 2.98 | BC15: 2.47 | BD15: 2.14 | BE15: 2.72 | BF15: 0.59 | BG15: 1.68 | BH15: 1.72 | BI15: 2.88 | BJ15: 2.28 | BK15: 2.13 | BL15: 1.65 | BM15: 1.42 | BN15: 1.35 | BO15: 1.19 | BP15: 0.93 | BQ15: =ROUND(('Annual Change'!BQ15/Population!BP15)*100,2) -> 2.57
A16: Garfield | B16: Garfield County | C16: . | D16: -2.55 | E16: 0 | F16: -6.9 | G16: 0 | H16: 3.7 | I16: 0 | J16: 3.57 | K16: 0 | L16: -3.45 | M16: 3.96 | N16: 6.49 | O16: 3.23 | P16: -6.25 | Q16: -6.67 | R16: 0 | S16: 3.57 | T16: 0 | U16: -6.9 | V16: -3.7 | W16: -5.08 | X16: -0.08 | Y16: -1.18 | Z16: 0.41 | AA16: -0.25 | AB16: -0.94 | AC16: -0.91 | AD16: -2.59 | AE16: -0.34 | AF16: -3.14 | AG16: -0.22 | AH16: 0.49 | AI16: 0.58 | AJ16: -0.18 | AK16: 1.85 | AL16: 0.52 | AM16: 0.95 | AN16: 0.43 | AO16: 0.25 | AP16: 0.51 | AQ16: 1.05 | AR16: -0.63 | AS16: -0.71 | AT16: -0.72 | AU16: -0.98 | AV16: -0.43 | AW16: -0.39 | AX16: -0.82 | AY16: -0.39 | AZ16: -0.26 | BA16: -0.26 | BB16: 0 | BC16: -0.26 | BD16: 0 | BE16: -0.35 | BF16: 1.24 | BG16: -0.61 | BH16: -0.13 | BI16: 0.27 | BJ16: 0.4 | BK16: 0.35 | BL16: 0.61 | BM16: 0 | BN16: 0 | BO16: 1.09 | BP16: -1.08 | BQ16: =ROUND(('Annual Change'!BQ16/Population!BP16)*100,2) -> 0
... A44: State | B44: State Total | C44: . | D44: 1.53 | E44: 1.76 | F44: 0.81 | G44: 1.21 | H44: 1.89 | I44: 1.96 | J44: 3.33 | K44: 3.31 | L44: 1.83 | M44: 0.48 | N44: 0.68 | O44: -0.17 | P44: 0.41 | Q44: 1.87 | R44: 1.69 | S44: 1.88 | T44: 2.21 | U44: 3.25 | V44: 3.73 | W44: 3.85 | X44: 2.35 | Y44: 1.12 | Z44: 0.72 | AA44: 1.09 | AB44: 1.42 | AC44: 1.05 | AD44: 1.45 | AE44: 1.98 | AF44: 2.41 | AG44: 2.93 | AH44: 2.75 | AI44: 1.82 | AJ44: 1.9 | AK44: 2 | AL44: 1.98 | AM44: 1.6 | AN44: 1.75 | AO44: 1.91 | AP44: 1.88 | AQ44: 1.76 | AR44: 1.29 | AS44: 1.49 | AT44: 1.11 | AU44: 1.33 | AV44: 1.45 | AW44: 1.93 | AX44: 1.63 | AY44: 1.27 | AZ44: 0.97 | BA44: 0.78 | BB44: 0.79 | BC44: 0.79 | BD44: 1.09 | BE44: 1.44 | BF44: 1.45 | BG44: 1.84 | BH44: 1.48 | BI44: 1.63 | BJ44: 1.59 | BK44: 1.64 | BL44: 0.79 | BM44: 1.25 | BN44: 1.1 | BO44: 1.06 | BP44: 0.99 | BQ44: =ROUND(('Annual Change'!BQ44/Population!BP44)*100,2) -> 0.75

Sheet Births
A1: Population and Components of Change, Births, 1960 to Present
A2: Office of Financial Management, Forecasting and Research Division
A4: County | B4: Jurisdiction | C4: Spacer | D4: Births1960-1961 | E4: Births 1961-1962 | F4: Births 1962-1963 | G4: Births 1963-1964 | H4: Births 1964-1965 | I4: Births 1965-1966 | J4: Births 1966-1967 | K4: Births 1967-1968 | L4: Births 1968-1969 | M4: Births 1969-1970 | N4: Births 1970-1971 | O4: Births 1971-1972 | P4: Births 1972-1973 | Q4: Births 1973-1974 | R4: Births 1974-1975 | S4: Births 1975-1976 | T4: Births 1976-1977 | U4: Births 1977-1978 | V4: Births 1978-1979 | W4: Births 1979-1980 | X4: Births 1980-1981 | Y4: Births 1981-1982 | Z4: Births 1982-1983 | AA4: Births 1983-1984 | AB4: Births 1984-1985 | AC4: Births 1985-1986 | AD4: Births 1986-1987 | AE4: Births 1987-1988 | AF4: Births 1988-1989 | AG4: Births 1989-1990 | AH4: Births 1990-1991 | AI4: Births 1991-1992 | AJ4: Births 1992-1993 | AK4: Births 1993-1994 | AL4: Births 1994-1995 | AM4: Births 1995-1996 | AN4: Births 1996-1997 | AO4: Births 1997-1998 | AP4: Births 1998-1999 | AQ4: Births 1999-2000 | AR4: Births 2000-2001 | AS4: Births 2001-2002 | AT4: Births 2002-2003 | AU4: Births 2003-2004 | AV4: Births 2004-2005 | AW4: Births 2005-2006 | AX4: Births 2006-2007 | AY4: Births 2007-2008 | AZ4: Births 2008-2009 | BA4: Births 2009-2010 | BB4: Births 2010-2011 | BC4: Births 2011-2012 | BD4: Births 2012-2013 | BE4: Births 2013-2014 | BF4: Births 2014-2015 | BG4: Births 2015-2016 | BH4: Births 2016-2017 | BI4: Births 2017-2018 | BJ4: Births 2018-2019 | BK4: Births 2019-2020 | BL4: Births 2020-2021 | BM4: Births 2021-2022 | BN4: Births 2022-2023 | BO4: Births 2023-2024 | BP4: Births 2024-2025 | BQ4: Births 2025-2026
A5: Adams | B5: Adams County | C5: . | D5: 250 | E5: 252 | F5: 294 | G5: 218 | H5: 252 | I5: 187 | J5: 201 | K5: 227 | L5: 230 | M5: 216 | N5: 261 | O5: 263 | P5: 228 | Q5: 238 | R5: 256 | S5: 282 | T5: 314 | U5: 330 | V5: 320 | W5: 304 | X5: 308 | Y5: 307 | Z5: 287 | AA5: 296 | AB5: 306 | AC5: 282 | AD5: 259 | AE5: 267 | AF5: 267 | AG5: 259 | AH5: 276 | AI5: 301 | AJ5: 313 | AK5: 327 | AL5: 315 | AM5: 294 | AN5: 303 | AO5: 288 | AP5: 328 | AQ5: 346 | AR5: 321 | AS5: 326 | AT5: 357 | AU5: 331 | AV5: 416 | AW5: 414 | AX5: 393 | AY5: 425 | AZ5: 440 | BA5: 415 | BB5: 478 | BC5: 394 | BD5: 381 | BE5: 413 | BF5: 367 | BG5: 361 | BH5: 369 | BI5: 395 | BJ5: 383 | BK5: 377 | BL5: 339 | BM5: 346 | BN5: 351 | BO5: 351 | BP5: 376 | BQ5: 358
A6: Asotin | B6: Asotin County | C6: . | D6: 283 | E6: 247 | F6: 255 | G6: 244 | H6: 229 | I6: 207 | J6: 205 | K6: 202 | L6: 209 | M6: 226 | N6: 217 | O6: 233 | P6: 189 | Q6: 250 | R6: 225 | S6: 209 | T6: 234 | U6: 231 | V6: 266 | W6: 271 | X6: 246 | Y6: 283 | Z6: 245 | AA6: 268 | AB6: 263 | AC6: 262 | AD6: 250 | AE6: 229 | AF6: 236 | AG6: 276 | AH6: 255 | AI6: 267 | AJ6: 278 | AK6: 246 | AL6: 263 | AM6: 242 | AN6: 251 | AO6: 278 | AP6: 288 | AQ6: 263 | AR6: 247 | AS6: 225 | AT6: 242 | AU6: 289 | AV6: 252 | AW6: 238 | AX6: 240 | AY6: 242 | AZ6: 245 | BA6: 217 | BB6: 243 | BC6: 236 | BD6: 249 | BE6: 242 | BF6: 257 | BG6: 220 | BH6: 216 | BI6: 208 | BJ6: 237 | BK6: 227 | BL6: 207 | BM6: 224 | BN6: 202 | BO6: 214 | BP6: 178 | BQ6: 201
A7: Benton | B7: Benton County | D7: 1562 | E7: 1519 | F7: 1368 | G7: 1329 | H7: 1280 | I7: 1128 | J7: 1090 | K7: 1042 | L7: 991 | M7: 1103 | N7: 1071 | O7: 1103 | P7: 991 | Q7: 970 | R7: 1101 | S7: 1181 | T7: 1390 | U7: 1485 | V7: 1812 | W7: 2003 | X7: 2089 | Y7: 2256 | Z7: 2126 | AA7: 2056 | AB7: 1981 | AC7: 1880 | AD7: 1880 | AE7: 1822 | AF7: 1756 | AG7: 1830 | AH7: 1874 | AI7: 1942 | AJ7: 1973 | AK7: 1976 | AL7: 1940 | AM7: 2026 | AN7: 2023 | AO7: 2000 | AP7: 2079 | AQ7: 2135 | AR7: 2094 | AS7: 2217 | AT7: 2147 | AU7: 2186 | AV7: 2140 | AW7: 2193 | AX7: 2428 | AY7: 2412 | AZ7: 2483 | BA7: 2467 | BB7: 2569 | BC7: 2558 | BD7: 2539 | BE7: 2549 | BF7: 2674 | BG7: 2696 | BH7: 2713 | BI7: 2552 | BJ7: 2580 | BK7: 2540 | BL7: 2470 | BM7: 2590 | BN7: 2441 | BO7: 2520 | BP7: 2649 | BQ7: 2592
A8: Chelan | B8: Chelan County | C8: . | D8: 799 | E8: 774 | F8: 683 | G8: 750 | H8: 678 | I8: 600 | J8: 622 | K8: 601 | L8: 598 | M8: 584 | N8: 622 | O8: 523 | P8: 491 | Q8: 466 | R8: 492 | S8: 562 | T8: 549 | U8: 656 | V8: 687 | W8: 739 | X8: 830 | Y8: 755 | Z8: 770 | AA8: 846 | AB8: 847 | AC8: 887 | AD8: 821 | AE8: 841 | AF8: 839 | AG8: 909 | AH8: 983 | AI8: 934 | AJ8: 968 | AK8: 1001 | AL8: 982 | AM8: 944 | AN8: 997 | AO8: 969 | AP8: 1035 | AQ8: 984 | AR8: 960 | AS8: 966 | AT8: 881 | AU8: 906 | AV8: 907 | AW8: 944 | AX8: 971 | AY8: 1049 | AZ8: 1064 | BA8: 1033 | BB8: 983 | BC8: 931 | BD8: 909 | BE8: 899 | BF8: 957 | BG8: 941 | BH8: 920 | BI8: 862 | BJ8: 845 | BK8: 875 | BL8: 791 | BM8: 799 | BN8: 785 | BO8: 777 | BP8: 840 | BQ8: 857
A9: Clallam | B9: Clallam County | C9: . | D9: 712 | E9: 739 | F9: 638 | G9: 553 | H9: 548 | I9: 539 | J9: 486 | K9: 535 | L9: 514 | M9: 595 | N9: 572 | O9: 574 | P9: 563 | Q9: 610 | R9: 646 | S9: 619 | T9: 666 | U9: 784 | V9: 777 | W9: 905 | X9: 876 | Y9: 768 | Z9: 784 | AA9: 793 | AB9: 822 | AC9: 748 | AD9: 719 | AE9: 768 | AF9: 697 | AG9: 718 | AH9: 779 | AI9: 714 | AJ9: 646 | AK9: 689 | AL9: 608 | AM9: 652 | AN9: 644 | AO9: 652 | AP9: 676 | AQ9: 612 | AR9: 627 | AS9: 606 | AT9: 581 | AU9: 619 | AV9: 584 | AW9: 627 | AX9: 671 | AY9: 646 | AZ9: 630 | BA9: 659 | BB9: 677 | BC9: 673 | BD9: 643 | BE9: 694 | BF9: 667 | BG9: 686 | BH9: 650 | BI9: 641 | BJ9: 610 | BK9: 567 | BL9: 625 | BM9: 582 | BN9: 500 | BO9: 509 | BP9: 542 | BQ9: 540
A10: Clark | B10: Clark County | C10: . | D10: 2073 | E10: 2066 | F10: 2026 | G10: 1957 | H10: 1885 | I10: 1809 | J10: 1954 | K10: 1980 | L10: 2145 | M10: 2248 | N10: 2442 | O10: 2258 | P10: 2203 | Q10: 2212 | R10: 2381 | S10: 2487 | T10: 2544 | U10: 2747 | V10: 2977 | W10: 3239 | X10: 3354 | Y10: 3343 | Z10: 3267 | AA10: 3028 | AB10: 3181 | AC10: 3332 | AD10: 3162 | AE10: 3369 | AF10: 3490 | AG10: 3813 | AH10: 4085 | AI10: 4060 | AJ10: 4023 | AK10: 4190 | AL10: 4396 | AM10: 4528 | AN10: 4861 | AO10: 5010 | AP10: 5144 | AQ10: 5194 | AR10: 5432 | AS10: 5234 | AT10: 5263 | AU10: 5441 | AV10: 5545 | AW10: 5730 | AX10: 5823 | AY10: 5917 | AZ10: 5723 | BA10: 5598 | BB10: 5385 | BC10: 5420 | BD10: 5445 | BE10: 5338 | BF10: 5564 | BG10: 5620 | BH10: 5631 | BI10: 5495 | BJ10: 5479 | BK10: 5600 | BL10: 5299 | BM10: 5741 | BN10: 5393 | BO10: 5612 | BP10: 5682 | BQ10: 5700
A11: Columbia | B11: Columbia County | C11: . | D11: 75 | E11: 74 | F11: 90 | G11: 80 | H11: 70 | I11: 62 | J11: 71 | K11: 82 | L11: 55 | M11: 50 | N11: 38 | O11: 49 | P11: 58 | Q11: 42 | R11: 47 | S11: 61 | T11: 68 | U11: 62 | V11: 63 | W11: 66 | X11: 59 | Y11: 60 | Z11: 60 | AA11: 63 | AB11: 45 | AC11: 58 | AD11: 58 | AE11: 58 | AF11: 43 | AG11: 49 | AH11: 58 | AI11: 39 | AJ11: 61 | AK11: 38 | AL11: 47 | AM11: 48 | AN11: 50 | AO11: 39 | AP11: 50 | AQ11: 21 | AR11: 39 | AS11: 33 | AT11: 41 | AU11: 36 | AV11: 38 | AW11: 25 | AX11: 46 | AY11: 33 | AZ11: 40 | BA11: 36 | BB11: 38 | BC11: 30 | BD11: 33 | BE11: 37 | BF11: 42 | BG11: 31 | BH11: 38 | BI11: 35 | BJ11: 31 | BK11: 38 | BL11: 34 | BM11: 28 | BN11: 36 | BO11: 32 | BP11: 39 | BQ11: 32
A12: Cowlitz | B12: Cowlitz County | D12: 1342 | E12: 1279 | F12: 1273 | G12: 1217 | H12: 1187 | I12: 1237 | J12: 1160 | K12: 1194 | L12: 1223 | M12: 1292 | N12: 1444 | O12: 1215 | P12: 1060 | Q12: 1050 | R12: 1164 | S12: 1184 | T12: 1200 | U12: 1238 | V12: 1248 | W12: 1367 | X12: 1317 | Y12: 1280 | Z12: 1257 | AA12: 1201 | AB12: 1146 | AC12: 1090 | AD12: 1200 | AE12: 1208 | AF12: 1232 | AG12: 1325 | AH12: 1360 | AI12: 1319 | AJ12: 1213 | AK12: 1237 | AL12: 1207 | AM12: 1253 | AN12: 1234 | AO12: 1154 | AP12: 1254 | AQ12: 1270 | AR12: 1270 | AS12: 1246 | AT12: 1191 | AU12: 1140 | AV12: 1273 | AW12: 1271 | AX12: 1339 | AY12: 1369 | AZ12: 1335 | BA12: 1241 | BB12: 1228 | BC12: 1217 | BD12: 1147 | BE12: 1153 | BF12: 1180 | BG12: 1263 | BH12: 1296 | BI12: 1263 | BJ12: 1244 | BK12: 1260 | BL12: 1212 | BM12: 1216 | BN12: 1245 | BO12: 1216 | BP12: 1247 | BQ12: 1249
A13: Douglas | B13: Douglas County | C13: . | D13: 283 | E13: 303 | F13: 225 | G13: 221 | H13: 208 | I13: 215 | J13: 207 | K13: 214 | L13: 224 | M13: 228 | N13: 254 | O13: 226 | P13: 194 | Q13: 232 | R13: 220 | S13: 280 | T13: 308 | U13: 336 | V13: 364 | W13: 382 | X13: 375 | Y13: 387 | Z13: 367 | AA13: 358 | AB13: 355 | AC13: 374 | AD13: 359 | AE13: 335 | AF13: 371 | AG13: 404 | AH13: 452 | AI13: 396 | AJ13: 414 | AK13: 457 | AL13: 461 | AM13: 432 | AN13: 453 | AO13: 453 | AP13: 430 | AQ13: 472 | AR13: 440 | AS13: 439 | AT13: 444 | AU13: 441 | AV13: 460 | AW13: 522 | AX13: 527 | AY13: 580 | AZ13: 590 | BA13: 515 | BB13: 532 | BC13: 534 | BD13: 509 | BE13: 511 | BF13: 530 | BG13: 536 | BH13: 509 | BI13: 547 | BJ13: 482 | BK13: 500 | BL13: 474 | BM13: 517 | BN13: 493 | BO13: 478 | BP13: 518 | BQ13: 516
A14: Ferry | B14: Ferry County | C14: . | D14: 84 | E14: 92 | F14: 86 | G14: 68 | H14: 80 | I14: 65 | J14: 57 | K14: 55 | L14: 73 | M14: 51 | N14: 60 | O14: 81 | P14: 60 | Q14: 77 | R14: 76 | S14: 75 | T14: 66 | U14: 84 | V14: 82 | W14: 123 | X14: 112 | Y14: 126 | Z14: 105 | AA14: 108 | AB14: 101 | AC14: 80 | AD14: 81 | AE14: 78 | AF14: 78 | AG14: 82 | AH14: 81 | AI14: 97 | AJ14: 84 | AK14: 80 | AL14: 85 | AM14: 84 | AN14: 78 | AO14: 79 | AP14: 76 | AQ14: 73 | AR14: 77 | AS14: 69 | AT14: 78 | AU14: 65 | AV14: 82 | AW14: 76 | AX14: 63 | AY14: 66 | AZ14: 66 | BA14: 68 | BB14: 59 | BC14: 75 | BD14: 72 | BE14: 66 | BF14: 76 | BG14: 66 | BH14: 78 | BI14: 67 | BJ14: 64 | BK14: 72 | BL14: 61 | BM14: 74 | BN14: 58 | BO14: 73 | BP14: 61 | BQ14: 71
A15: Franklin | B15: Franklin County | C15: . | D15: 554 | E15: 527 | F15: 515 | G15: 530 | H15: 471 | I15: 473 | J15: 432 | K15: 445 | L15: 413 | M15: 487 | N15: 471 | O15: 493 | P15: 497 | Q15: 477 | R15: 550 | S15: 564 | T15: 715 | U15: 724 | V15: 847 | W15: 898 | X15: 919 | Y15: 904 | Z15: 899 | AA15: 869 | AB15: 775 | AC15: 757 | AD15: 730 | AE15: 747 | AF15: 784 | AG15: 778 | AH15: 933 | AI15: 984 | AJ15: 948 | AK15: 984 | AL15: 1004 | AM15: 1009 | AN15: 1029 | AO15: 1000 | AP15: 1052 | AQ15: 1090 | AR15: 1093 | AS15: 1183 | AT15: 1224 | AU15: 1307 | AV15: 1382 | AW15: 1494 | AX15: 1534 | AY15: 1627 | AZ15: 1677 | BA15: 1666 | BB15: 1681 | BC15: 1742 | BD15: 1634 | BE15: 1616 | BF15: 1651 | BG15: 1659 | BH15: 1628 | BI15: 1563 | BJ15: 1507 | BK15: 1524 | BL15: 1462 | BM15: 1465 | BN15: 1438 | BO15: 1454 | BP15: 1522 | BQ15: 1513
A16: Garfield | B16: Garfield County | C16: . | D16: 66 | E16: 73 | F16: 50 | G16: 51 | H16: 35 | I16: 30 | J16: 45 | K16: 57 | L16: 51 | M16: 35 | N16: 53 | O16: 32 | P16: 31 | Q16: 37 | R16: 49 | S16: 33 | T16: 47 | U16: 38 | V16: 41 | W16: 32 | X16: 44 | Y16: 41 | Z16: 43 | AA16: 39 | AB16: 32 | AC16: 27 | AD16: 22 | AE16: 24 | AF16: 13 | AG16: 25 | AH16: 27 | AI16: 22 | AJ16: 18 | AK16: 18 | AL16: 17 | AM16: 24 | AN16: 18 | AO16: 15 | AP16: 18 | AQ16: 27 | AR16: 24 | AS16: 20 | AT16: 14 | AU16: 15 | AV16: 15 | AW16: 13 | AX16: 19 | AY16: 13 | AZ16: 26 | BA16: 17 | BB16: 22 | BC16: 21 | BD16: 14 | BE16: 23 | BF16: 24 | BG16: 29 | BH16: 30 | BI16: 24 | BJ16: 20 | BK16: 23 | BL16: 19 | BM16: 26 | BN16: 26 | BO16: 18 | BP16: 26 | BQ16: 20
A17: Grant | B17: Grant County | D17: 1416 | E17: 1644 | F17: 1479 | G17: 1292 | H17: 1113 | I17: 914 | J17: 670 | K17: 705 | L17: 710 | M17: 701 | N17: 833 | O17: 750 | P17: 726 | Q17: 715 | R17: 742 | S17: 803 | T17: 914 | U17: 912 | V17: 893 | W17: 959 | X17: 952 | Y17: 922 | Z17: 927 | AA17: 977 | AB17: 921 | AC17: 1029 | AD17: 899 | AE17: 935 | AF17: 883 | AG17: 941 | AH17: 1011 | AI17: 1138 | AJ17: 1112 | AK17: 1145 | AL17: 1214 | AM17: 1267 | AN17: 1334 | AO17: 1383 | AP17: 1318 | AQ17: 1424 | AR17: 1410 | AS17: 1313 | AT17: 1387 | AU17: 1433 | AV17: 1450 | AW17: 1487 | AX17: 1543 | AY17: 1596 | AZ17: 1616 | BA17: 1644 | BB17: 1619 | BC17: 1587 | BD17: 1562 | BE17: 1477 | BF17: 1487 | BG17: 1495 | BH17: 1476 | BI17: 1469 | BJ17: 1494 | BK17: 1407 | BL17: 1375 | BM17: 1358 | BN17: 1401 | BO17: 1403 | BP17: 1580 | BQ17: 1470
A18: Grays Harbor | B18: Grays Harbor County | C18: . | D18: 1161 | E18: 1037 | F18: 1106 | G18: 1024 | H18: 1096 | I18: 1053 | J18: 1000 | K18: 943 | L18: 1001 | M18: 1052 | N18: 1079 | O18: 949 | P18: 942 | Q18: 845 | R18: 924 | S18: 865 | T18: 983 | U18: 1031 | V18: 1079 | W18: 1199 | X18: 1124 | Y18: 1069 | Z18: 1106 | AA18: 1018 | AB18: 1053 | AC18: 1028 | AD18: 922 | AE18: 896 | AF18: 953 | AG18: 933 | AH18: 940 | AI18: 1006 | AJ18: 910 | AK18: 854 | AL18: 856 | AM18: 880 | AN18: 867 | AO18: 859 | AP18: 853 | AQ18: 824 | AR18: 791 | AS18: 765 | AT18: 823 | AU18: 808 | AV18: 845 | AW18: 852 | AX18: 883 | AY18: 891 | AZ18: 894 | BA18: 813 | BB18: 846 | BC18: 803 | BD18: 793 | BE18: 752 | BF18: 764 | BG18: 794 | BH18: 748 | BI18: 733 | BJ18: 717 | BK18: 701 | BL18: 693 | BM18: 695 | BN18: 659 | BO18: 687 | BP18: 654 | BQ18: 610
